Workbook

Sheet Raw Data
B1: Security | C1: LyondellBasell Industries NV | D1: American Express Co | E1: Verizon Communications Inc | F1: Texas Pacific Land Corp | G1: Broadcom Inc | H1: Boeing Co/The | I1: Caterpillar Inc | J1: JPMorgan Chase & Co | K1: Chevron Corp | L1: Coca-Cola Co/The | M1: AbbVie Inc | N1: Walt Disney Co/The | O1: Corpay Inc | P1: Extra Space Storage Inc | Q1: Exxon Mobil Corp | R1: Phillips 66 | S1: General Electric Co | T1: HP Inc | U1: Home Depot Inc/The | V1: Monolithic Power Systems Inc | W1: International Business Machines Corp | X1: Johnson & Johnson | Y1: Lululemon Athletica Inc | Z1: McDonald's Corp | AA1: Merck & Co Inc | AB1: 3M Co | AC1: American Water Works Co Inc | AD1: Bank of America Corp | AE1: Pfizer Inc | AF1: Procter & Gamble Co/The | AG1: AT&T Inc | AH1: Travelers Cos Inc/The | AI1: RTX Corp | AJ1: Analog Devices Inc | AK1: Walmart Inc | AL1: Cisco Systems Inc | AM1: Intel Corp | AN1: General Motors Co | AO1: Microsoft Corp | AP1: Dollar General Corp | AQ1: Cigna Group/The | AR1: Kinder Morgan Inc | AS1: Citigroup Inc | AT1: American International Group Inc | AU1: Altria Group Inc | AV1: HCA Healthcare Inc | AW1: International Paper Co | AX1: Hewlett Packard Enterprise Co | AY1: Abbott Laboratories | AZ1: Aflac Inc | BA1: Air Products and Chemicals Inc | BB1: Royal Caribbean Cruises Ltd | BC1: Interactive Brokers Group Inc | BD1: Lennox International Inc | BE1: Archer-Daniels-Midland Co | BF1: EMCOR Group Inc | BG1: Automatic Data Processing Inc | BH1: Verisk Analytics Inc | BI1: AutoZone Inc | BJ1: Avery Dennison Corp | BK1: MSCI Inc | BL1: Ball Corp | BM1: Axon Enterprise Inc | BN1: Dayforce Inc | BO1: Bank of New York Mellon Corp/The | BP1: Baxter International Inc | BQ1: Becton Dickinson & Co | BR1: Berkshire Hathaway Inc | BS1: Best Buy Co Inc | BT1: Boston Scientific Corp | BU1: Bristol-Myers Squibb Co | BV1: Brown-Forman Corp | BW1: Coterra Energy Inc | BX1: Hilton Worldwide Holdings Inc | BY1: Carnival Corp | BZ1: Builders FirstSource Inc | CA1: UDR Inc | CB1: Clorox Co/The | CC1: Paycom Software Inc | CD1: CMS Energy Corp | CE1: Colgate-Palmolive Co | CF1: EPAM Systems Inc | CG1: Conagra Brands Inc | CH1: Consolidated Edison Inc | CI1: Corning Inc | CJ1: GoDaddy Inc | CK1: Cummins Inc | CL1: Danaher Corp | CM1: Target Corp | CN1: Williams-Sonoma Inc | CO1: Deere & Co | CP1: Dominion Energy Inc | CQ1: Trade Desk Inc/The | CR1: Dover Corp | CS1: Alliant Energy Corp | CT1: Steel Dynamics Inc | CU1: Duke Energy Corp | CV1: Regency Centers Corp | CW1: Eaton Corp PLC | CX1: Ecolab Inc | CY1: Revvity Inc | CZ1: Dell Technologies Inc | DA1: Emerson Electric Co | DB1: EOG Resources Inc | DC1: Aon PLC | DD1: Entergy Corp | DE1: Equifax Inc | DF1: EQT Corp | DG1: IQVIA Holdings Inc | DH1: Gartner Inc | DI1: FedEx Corp | DJ1: Brown & Brown Inc | DK1: Ford Motor Co | DL1: NextEra Energy Inc | DM1: Franklin Resources Inc | DN1: Garmin Ltd | DO1: Freeport-McMoRan Inc | DP1: Dexcom Inc | DQ1: General Dynamics Corp | DR1: General Mills Inc | DS1: Genuine Parts Co | DT1: Atmos Energy Corp | DU1: WW Grainger Inc | DV1: Halliburton Co | DW1: L3Harris Technologies Inc | DX1: Healthpeak Properties Inc | DY1: Insulet Corp | DZ1: Fortive Corp | EA1: Hershey Co/The | EB1: Synchrony Financial | EC1: Hormel Foods Corp | ED1: Arthur J Gallagher & Co | EE1: Mondelez International Inc | EF1: CenterPoint Energy Inc | EG1: Humana Inc | EH1: Willis Towers Watson PLC | EI1: Illinois Tool Works Inc | EJ1: CDW Corp/DE | EK1: Trane Technologies PLC | EL1: International Flavors & Fragrances Inc | EM1: Generac Holdings Inc | EN1: NXP Semiconductors NV | EO1: Kellanova | EP1: Broadridge Financial Solutions Inc | EQ1: Kimco Realty Corp | ER1: Oracle Corp | ES1: Kroger Co/The | ET1: Lennar Corp | EU1: Eli Lilly & Co | EV1: Charter Communications Inc | EW1: Loews Corp | EX1: Lowe's Cos Inc | EY1: Hubbell Inc | EZ1: IDEX Corp | FA1: Marsh & McLennan Cos Inc | FB1: Masco Corp | FC1: S&P Global Inc | FD1: Medtronic PLC | FE1: Viatris Inc | FF1: CVS Health Corp | FG1: DuPont de Nemours Inc | FH1: Micron Technology Inc | FI1: Motorola Solutions Inc | FJ1: Cboe Global Markets Inc | FK1: Newmont Corp | FL1: NIKE Inc | FM1: NiSource Inc | FN1: Norfolk Southern Corp | FO1: Principal Financial Group Inc | FP1: Eversource Energy | FQ1: Northrop Grumman Corp | FR1: Wells Fargo & Co | FS1: Nucor Corp | FT1: Occidental Petroleum Corp | FU1: Omnicom Group Inc | FV1: ONEOK Inc | FW1: Raymond James Financial Inc | FX1: PG&E Corp | FY1: Parker-Hannifin Corp | FZ1: Rollins Inc | GA1: PPL Corp | GB1: Aptiv PLC | GC1: ConocoPhillips | GD1: PulteGroup Inc | GE1: Pinnacle West Capital Corp | GF1: PNC Financial Services Group Inc/The | GG1: PPG Industries Inc | GH1: Progressive Corp/The | GI1: Public Service Enterprise Group Inc | GJ1: Edison International | GK1: SLB Ltd | GL1: Charles Schwab Corp/The | GM1: Sherwin-Williams Co/The | GN1: West Pharmaceutical Services Inc | GO1: J M Smucker Co/The | GP1: Snap-on Inc | GQ1: AMETEK Inc | GR1: Uber Technologies Inc | GS1: Southern Co/The | GT1: Truist Financial Corp | GU1: Southwest Airlines Co | GV1: W R Berkley Corp | GW1: Stanley Black & Decker Inc | GX1: Public Storage | GY1: Arista Networks Inc | GZ1: Sysco Corp | HA1: Corteva Inc | HB1: Texas Instruments Inc | HC1: Textron Inc | HD1: Thermo Fisher Scientific Inc | HE1: TJX Cos Inc/The | HF1: Globe Life Inc | HG1: Johnson Controls International plc | HH1: Ulta Beauty Inc | HI1: Union Pacific Corp | HJ1: Keysight Technologies Inc | HK1: UnitedHealth Group Inc | HL1: Blackstone Inc | HM1: Ventas Inc | HN1: Labcorp Holdings Inc | HO1: Vulcan Materials Co | HP1: Weyerhaeuser Co | HQ1: Williams Cos Inc/The | HR1: WEC Energy Group Inc | HS1: Adobe Inc | HT1: Vistra Corp | HU1: AES Corp/The | HV1: Expeditors International of Washington Inc | HW1: Amgen Inc | HX1: Apple Inc | HY1: Autodesk Inc | HZ1: Cintas Corp | IA1: Comcast Corp | IB1: Molson Coors Beverage Co | IC1: KLA Corp | ID1: Marriott International Inc/MD | IE1: McCormick & Co Inc/MD | IF1: PACCAR Inc | IG1: Costco Wholesale Corp | IH1: Stryker Corp | II1: Tyson Foods Inc | IJ1: Lamb Weston Holdings Inc | IK1: Applied Materials Inc | IL1: Cardinal Health Inc | IM1: Cincinnati Financial Corp | IN1: DR Horton Inc | IO1: Electronic Arts Inc | IP1: Erie Indemnity Co | IQ1: Fair Isaac Corp | IR1: Fastenal Co | IS1: M&T Bank Corp | IT1: Xcel Energy Inc | IU1: Fifth Third Bancorp | IV1: Gilead Sciences Inc | IW1: Hasbro Inc | IX1: Huntington Bancshares Inc/OH | IY1: Welltower Inc | IZ1: Biogen Inc | JA1: Northern Trust Corp | JB1: Packaging Corp of America | JC1: Paychex Inc | JD1: QUALCOMM Inc | JE1: Ross Stores Inc | JF1: IDEXX Laboratories Inc | JG1: Starbucks Corp | JH1: KeyCorp | JI1: Fox Corp (Class A) | JJ1: Fox Corp | JK1: State Street Corp | JL1: Norwegian Cruise Line Holdings Ltd | JM1: US Bancorp | JN1: A O Smith Corp | JO1: Gen Digital Inc | JP1: T Rowe Price Group Inc | JQ1: Waste Management Inc | JR1: Constellation Brands Inc | JS1: Invesco Ltd | JT1: Intuit Inc | JU1: Morgan Stanley | JV1: Microchip Technology Inc | JW1: Crowdstrike Holdings Inc | JX1: Chubb Ltd | JY1: Hologic Inc | JZ1: Citizens Financial Group Inc | KA1: Jabil Inc | KB1: O'Reilly Automotive Inc | KC1: Allstate Corp/The | KD1: Equity Residential | KE1: Incyte Corp | KF1: Simon Property Group Inc | KG1: AvalonBay Communities Inc | KH1: Prudential Financial Inc | KI1: United Parcel Service Inc | KJ1: STERIS PLC | KK1: McKesson Corp | KL1: Lockheed Martin Corp | KM1: Cencora Inc | KN1: Capital One Financial Corp | KO1: Waters Corp | KP1: Nordson Corp | KQ1: Dollar Tree Inc | KR1: Darden Restaurants Inc | KS1: NVR Inc | KT1: NetApp Inc | KU1: Old Dominion Freight Line Inc | KV1: DaVita Inc | KW1: Hartford Insurance Group Inc/The | KX1: Iron Mountain Inc | KY1: Estee Lauder Cos Inc/The | KZ1: Cadence Design Systems Inc | LA1: Tyler Technologies Inc | LB1: Universal Health Services Inc | LC1: Skyworks Solutions Inc | LD1: Quest Diagnostics Inc | LE1: Rockwell Automation Inc | LF1: Kraft Heinz Co/The | LG1: American Tower Corp | LH1: Regeneron Pharmaceuticals Inc | LI1: Amazon.com Inc | LJ1: Jack Henry & Associates Inc | LK1: Ralph Lauren Corp | LL1: BXP Inc | LM1: Amphenol Corp | LN1: Howmet Aerospace Inc | LO1: Valero Energy Corp | LP1: Synopsys Inc | LQ1: CH Robinson Worldwide Inc | LR1: Accenture PLC | LS1: TransDigm Group Inc | LT1: Yum! Brands Inc | LU1: Prologis Inc | LV1: FirstEnergy Corp | LW1: VeriSign Inc | LX1: Quanta Services Inc | LY1: Henry Schein Inc | LZ1: Ameren Corp | MA1: FactSet Research Systems Inc | MB1: NVIDIA Corp | MC1: Cognizant Technology Solutions Corp | MD1: Intuitive Surgical Inc | ME1: Take-Two Interactive Software Inc | MF1: Republic Services Inc | MG1: eBay Inc | MH1: Goldman Sachs Group Inc/The | MI1: SBA Communications Corp | MJ1: Sempra | MK1: Moody's Corp | ML1: ON Semiconductor Corp | MM1: Booking Holdings Inc | MN1: F5 Inc | MO1: Akamai Technologies Inc | MP1: Charles River Laboratories International Inc | MQ1: Devon Energy Corp | MR1: Bio-Techne Corp | MS1: Alphabet Inc (Class A) | MT1: Allegion plc | MU1: Netflix Inc | MV1: Agilent Technologies Inc | MW1: Trimble Inc | MX1: Elevance Health Inc | MY1: CME Group Inc | MZ1: DTE Energy Co | NA1: Nasdaq Inc | NB1: Philip Morris International Inc | NC1: Ingersoll Rand Inc | ND1: Salesforce Inc | NE1: Huntington Ingalls Industries Inc | NF1: MetLife Inc | NG1: Tapestry Inc | NH1: CSX Corp | NI1: Edwards Lifesciences Corp | NJ1: Ameriprise Financial Inc | NK1: Zebra Technologies Corp | NL1: Zimmer Biomet Holdings Inc | NM1: Camden Property Trust | NN1: CBRE Group Inc | NO1: Mastercard Inc | NP1: Datadog Inc | NQ1: Intercontinental Exchange Inc | NR1: Fidelity National Information Services Inc | NS1: Chipotle Mexican Grill Inc | NT1: Wynn Resorts Ltd | NU1: Live Nation Entertainment Inc | NV1: Assurant Inc | NW1: NRG Energy Inc | NX1: Monster Beverage Corp | NY1: Regions Financial Corp | NZ1: Mosaic Co/The | OA1: Expedia Group Inc | OB1: CF Industries Holdings Inc | OC1: Leidos Holdings Inc | OD1: Alphabet Inc | OE1: TKO Group Holdings Inc | OF1: First Solar Inc | OG1: Visa Inc | OH1: Mid-America Apartment Communities Inc | OI1: Xylem Inc/NY | OJ1: Marathon Petroleum Corp | OK1: Tractor Supply Co | OL1: Advanced Micro Devices Inc | OM1: ResMed Inc | ON1: Mettler-Toledo International Inc | OO1: VICI Properties Inc | OP1: Copart Inc | OQ1: Jacobs Solutions Inc | OR1: Albemarle Corp | OS1: Fortinet Inc | OT1: Moderna Inc | OU1: Essex Property Trust Inc | OV1: CoStar Group Inc | OW1: Realty Income Corp | OX1: Westinghouse Air Brake Technologies Corp | OY1: Pool Corp | OZ1: Western Digital Corp | PA1: PepsiCo Inc | PB1: TE Connectivity PLC | PC1: Diamondback Energy Inc | PD1: ServiceNow Inc | PE1: Church & Dwight Co Inc | PF1: Federal Realty Investment Trust | PG1: MGM Resorts International | PH1: Invitation Homes Inc | PI1: PTC Inc | PJ1: JB Hunt Transport Services Inc | PK1: Lam Research Corp | PL1: Mohawk Industries Inc | PM1: Pentair PLC | PN1: Vertex Pharmaceuticals Inc | PO1: Amcor PLC | PP1: Meta Platforms Inc | PQ1: T-Mobile US Inc | PR1: United Rentals Inc | PS1: Alexandria Real Estate Equities Inc | PT1: Delta Air Lines Inc | PU1: United Airlines Holdings Inc | PV1: Seagate Technology Holdings PLC | PW1: News Corp | PX1: Centene Corp | PY1: Block Inc | PZ1: Apollo Global Management Inc | QA1: Martin Marietta Materials Inc | QB1: Teradyne Inc | QC1: PayPal Holdings Inc | QD1: Tesla Inc | QE1: Blackrock Inc | QF1: KKR & Co Inc | QG1: Arch Capital Group Ltd | QH1: Dow Inc | QI1: Everest Group Ltd | QJ1: Teledyne Technologies Inc | QK1: News Corp (Class A) | QL1: Exelon Corp | QM1: Global Payments Inc | QN1: Crown Castle Inc | QO1: Align Technology Inc | QP1: Targa Resources Corp | QQ1: Bunge Global SA | QR1: LKQ Corp | QS1: Deckers Outdoor Corp | QT1: Workday Inc | QU1: Zoetis Inc | QV1: Equinix Inc | QW1: Digital Realty Trust Inc | QX1: Molina Healthcare Inc | QY1: Las Vegas Sands Corp | QZ1: Solventum Corp | RA1: Super Micro Computer Inc | RB1: Linde PLC | RC1: Carrier Global Corp | RD1: Otis Worldwide Corp | RE1: Airbnb Inc | RF1: Expand Energy Corp | RG1: DoorDash Inc | RH1: Veralto Corp | RI1: Cooper Cos Inc/The | RJ1: Constellation Energy Corp | RK1: AppLovin Corp | RL1: Keurig Dr Pepper Inc | RM1: Host Hotels & Resorts Inc | RN1: Campbell's Company/The | RO1: Evergy Inc | RP1: Match Group Inc | RQ1: Warner Bros Discovery Inc | RR1: Roper Technologies Inc | RS1: Smurfit WestRock PLC | RT1: Baker Hughes Co | RU1: APA Corp | RV1: Palantir Technologies Inc | RW1: Palo Alto Networks Inc | RX1: American Electric Power Co Inc | RY1: GE HealthCare Technologies Inc | RZ1: Honeywell International Inc | SA1: Robinhood Markets Inc | SB1: Domino's Pizza Inc | SC1: GE Vernova Inc | SD1: Kenvue Inc | SE1: Coinbase Global Inc
B2: Ticker | C2: LYB UN Equity | D2: AXP UN Equity | E2: VZ UN Equity | F2: TPL UN Equity | G2: AVGO UW Equity | H2: BA UN Equity | I2: CAT UN Equity | J2: JPM UN Equity | K2: CVX UN Equity | L2: KO UN Equity | M2: ABBV UN Equity | N2: DIS UN Equity | O2: CPAY UN Equity | P2: EXR UN Equity | Q2: XOM UN Equity | R2: PSX UN Equity | S2: GE UN Equity | T2: HPQ UN Equity | U2: HD UN Equity | V2: MPWR UW Equity | W2: IBM UN Equity | X2: JNJ UN Equity | Y2: LULU UW Equity | Z2: MCD UN Equity | AA2: MRK UN Equity | AB2: MMM UN Equity | AC2: AWK UN Equity | AD2: BAC UN Equity | AE2: PFE UN Equity | AF2: PG UN Equity | AG2: T UN Equity | AH2: TRV UN Equity | AI2: RTX UN Equity | AJ2: ADI UW Equity | AK2: WMT UN Equity | AL2: CSCO UW Equity | AM2: INTC UW Equity | AN2: GM UN Equity | AO2: MSFT UW Equity | AP2: DG UN Equity | AQ2: CI UN Equity | AR2: KMI UN Equity | AS2: C UN Equity | AT2: AIG UN Equity | AU2: MO UN Equity | AV2: HCA UN Equity | AW2: IP UN Equity | AX2: HPE UN Equity | AY2: ABT UN Equity | AZ2: AFL UN Equity | BA2: APD UN Equity | BB2: RCL UN Equity | BC2: IBKR UW Equity | BD2: LII UN Equity | BE2: ADM UN Equity | BF2: EME UN Equity | BG2: ADP UW Equity | BH2: VRSK UW Equity | BI2: AZO UN Equity | BJ2: AVY UN Equity | BK2: MSCI UN Equity | BL2: BALL UN Equity | BM2: AXON UW Equity | BN2: DAY UN Equity | BO2: BK UN Equity | BP2: BAX UN Equity | BQ2: BDX UN Equity | BR2: BRK/B UN Equity | BS2: BBY UN Equity | BT2: BSX UN Equity | BU2: BMY UN Equity | BV2: BF/B UN Equity | BW2: CTRA UN Equity | BX2: HLT UN Equity | BY2: CCL UN Equity | BZ2: BLDR UN Equity | CA2: UDR UN Equity | CB2: CLX UN Equity | CC2: PAYC UN Equity | CD2: CMS UN Equity | CE2: CL UN Equity | CF2: EPAM UN Equity | CG2: CAG UN Equity | CH2: ED UN Equity | CI2: GLW UN Equity | CJ2: GDDY UN Equity | CK2: CMI UN Equity | CL2: DHR UN Equity | CM2: TGT UN Equity | CN2: WSM UN Equity | CO2: DE UN Equity | CP2: D UN Equity | CQ2: TTD UQ Equity | CR2: DOV UN Equity | CS2: LNT UW Equity | CT2: STLD UW Equity | CU2: DUK UN Equity | CV2: REG UW Equity | CW2: ETN UN Equity | CX2: ECL UN Equity | CY2: RVTY UN Equity | CZ2: DELL UN Equity | DA2: EMR UN Equity | DB2: EOG UN Equity | DC2: AON UN Equity | DD2: ETR UN Equity | DE2: EFX UN Equity | DF2: EQT UN Equity | DG2: IQV UN Equity | DH2: IT UN Equity | DI2: FDX UN Equity | DJ2: BRO UN Equity | DK2: F UN Equity | DL2: NEE UN Equity | DM2: BEN UN Equity | DN2: GRMN UN Equity | DO2: FCX UN Equity | DP2: DXCM UW Equity | DQ2: GD UN Equity | DR2: GIS UN Equity | DS2: GPC UN Equity | DT2: ATO UN Equity | DU2: GWW UN Equity | DV2: HAL UN Equity | DW2: LHX UN Equity | DX2: DOC UN Equity | DY2: PODD UW Equity | DZ2: FTV UN Equity | EA2: HSY UN Equity | EB2: SYF UN Equity | EC2: HRL UN Equity | ED2: AJG UN Equity | EE2: MDLZ UW Equity | EF2: CNP UN Equity | EG2: HUM UN Equity | EH2: WTW UW Equity | EI2: ITW UN Equity | EJ2: CDW UW Equity | EK2: TT UN Equity | EL2: IFF UN Equity | EM2: GNRC UN Equity | EN2: NXPI UW Equity | EO2: K UN Equity | EP2: BR UN Equity | EQ2: KIM UN Equity | ER2: ORCL UN Equity | ES2: KR UN Equity | ET2: LEN UN Equity | EU2: LLY UN Equity | EV2: CHTR UW Equity | EW2: L UN Equity | EX2: LOW UN Equity | EY2: HUBB UN Equity | EZ2: IEX UN Equity | FA2: MMC UN Equity | FB2: MAS UN Equity | FC2: SPGI UN Equity | FD2: MDT UN Equity | FE2: VTRS UW Equity | FF2: CVS UN Equity | FG2: DD UN Equity | FH2: MU UW Equity | FI2: MSI UN Equity | FJ2: CBOE UF Equity | FK2: NEM UN Equity | FL2: NKE UN Equity | FM2: NI UN Equity | FN2: NSC UN Equity | FO2: PFG UW Equity | FP2: ES UN Equity | FQ2: NOC UN Equity | FR2: WFC UN Equity | FS2: NUE UN Equity | FT2: OXY UN Equity | FU2: OMC UN Equity | FV2: OKE UN Equity | FW2: RJF UN Equity | FX2: PCG UN Equity | FY2: PH UN Equity | FZ2: ROL UN Equity | GA2: PPL UN Equity | GB2: APTV UN Equity | GC2: COP UN Equity | GD2: PHM UN Equity | GE2: PNW UN Equity | GF2: PNC UN Equity | GG2: PPG UN Equity | GH2: PGR UN Equity | GI2: PEG UN Equity | GJ2: EIX UN Equity | GK2: SLB UN Equity | GL2: SCHW UN Equity | GM2: SHW UN Equity | GN2: WST UN Equity | GO2: SJM UN Equity | GP2: SNA UN Equity | GQ2: AME UN Equity | GR2: UBER UN Equity | GS2: SO UN Equity | GT2: TFC UN Equity | GU2: LUV UN Equity | GV2: WRB UN Equity | GW2: SWK UN Equity | GX2: PSA UN Equity | GY2: ANET UN Equity | GZ2: SYY UN Equity | HA2: CTVA UN Equity | HB2: TXN UW Equity | HC2: TXT UN Equity | HD2: TMO UN Equity | HE2: TJX UN Equity | HF2: GL UN Equity | HG2: JCI UN Equity | HH2: ULTA UW Equity | HI2: UNP UN Equity | HJ2: KEYS UN Equity | HK2: UNH UN Equity | HL2: BX UN Equity | HM2: VTR UN Equity | HN2: LH UN Equity | HO2: VMC UN Equity | HP2: WY UN Equity | HQ2: WMB UN Equity | HR2: WEC UN Equity | HS2: ADBE UW Equity | HT2: VST UN Equity | HU2: AES UN Equity | HV2: EXPD UN Equity | HW2: AMGN UW Equity | HX2: AAPL UW Equity | HY2: ADSK UW Equity | HZ2: CTAS UW Equity | IA2: CMCSA UW Equity | IB2: TAP UN Equity | IC2: KLAC UW Equity | ID2: MAR UW Equity | IE2: MKC UN Equity | IF2: PCAR UW Equity | IG2: COST UW Equity | IH2: SYK UN Equity | II2: TSN UN Equity | IJ2: LW UN Equity | IK2: AMAT UW Equity | IL2: CAH UN Equity | IM2: CINF UW Equity | IN2: DHI UN Equity | IO2: EA UW Equity | IP2: ERIE UW Equity | IQ2: FICO UN Equity | IR2: FAST UW Equity | IS2: MTB UN Equity | IT2: XEL UW Equity | IU2: FITB UW Equity | IV2: GILD UW Equity | IW2: HAS UW Equity | IX2: HBAN UW Equity | IY2: WELL UN Equity | IZ2: BIIB UW Equity | JA2: NTRS UW Equity | JB2: PKG UN Equity | JC2: PAYX UW Equity | JD2: QCOM UW Equity | JE2: ROST UW Equity | JF2: IDXX UW Equity | JG2: SBUX UW Equity | JH2: KEY UN Equity | JI2: FOXA UW Equity | JJ2: FOX UW Equity | JK2: STT UN Equity | JL2: NCLH UN Equity | JM2: USB UN Equity | JN2: AOS UN Equity | JO2: GEN UW Equity | JP2: TROW UW Equity | JQ2: WM UN Equity | JR2: STZ UN Equity | JS2: IVZ UN Equity | JT2: INTU UW Equity | JU2: MS UN Equity | JV2: MCHP UW Equity | JW2: CRWD UW Equity | JX2: CB UN Equity | JY2: HOLX UW Equity | JZ2: CFG UN Equity | KA2: JBL UN Equity | KB2: ORLY UW Equity | KC2: ALL UN Equity | KD2: EQR UN Equity | KE2: INCY UW Equity | KF2: SPG UN Equity | KG2: AVB UN Equity | KH2: PRU UN Equity | KI2: UPS UN Equity | KJ2: STE UN Equity | KK2: MCK UN Equity | KL2: LMT UN Equity | KM2: COR UN Equity | KN2: COF UN Equity | KO2: WAT UN Equity | KP2: NDSN UW Equity | KQ2: DLTR UW Equity | KR2: DRI UN Equity | KS2: NVR UN Equity | KT2: NTAP UW Equity | KU2: ODFL UW Equity | KV2: DVA UN Equity | KW2: HIG UN Equity | KX2: IRM UN Equity | KY2: EL UN Equity | KZ2: CDNS UW Equity | LA2: TYL UN Equity | LB2: UHS UN Equity | LC2: SWKS UW Equity | LD2: DGX UN Equity | LE2: ROK UN Equity | LF2: KHC UW Equity | LG2: AMT UN Equity | LH2: REGN UW Equity | LI2: AMZN UW Equity | LJ2: JKHY UW Equity | LK2: RL UN Equity | LL2: BXP UN Equity | LM2: APH UN Equity | LN2: HWM UN Equity | LO2: VLO UN Equity | LP2: SNPS UW Equity | LQ2: CHRW UW Equity | LR2: ACN UN Equity | LS2: TDG UN Equity | LT2: YUM UN Equity | LU2: PLD UN Equity | LV2: FE UN Equity | LW2: VRSN UW Equity | LX2: PWR UN Equity | LY2: HSIC UW Equity | LZ2: AEE UN Equity | MA2: FDS UN Equity | MB2: NVDA UW Equity | MC2: CTSH UW Equity | MD2: ISRG UW Equity | ME2: TTWO UW Equity | MF2: RSG UN Equity | MG2: EBAY UW Equity | MH2: GS UN Equity | MI2: SBAC UW Equity | MJ2: SRE UN Equity | MK2: MCO UN Equity | ML2: ON UW Equity | MM2: BKNG UW Equity | MN2: FFIV UW Equity | MO2: AKAM UW Equity | MP2: CRL UN Equity | MQ2: DVN UN Equity | MR2: TECH UW Equity | MS2: GOOGL UW Equity | MT2: ALLE UN Equity | MU2: NFLX UW Equity | MV2: A UN Equity | MW2: TRMB UW Equity | MX2: ELV UN Equity | MY2: CME UW Equity | MZ2: DTE UN Equity | NA2: NDAQ UW Equity | NB2: PM UN Equity | NC2: IR UN Equity | ND2: CRM UN Equity | NE2: HII UN Equity | NF2: MET UN Equity | NG2: TPR UN Equity | NH2: CSX UW Equity | NI2: EW UN Equity | NJ2: AMP UN Equity | NK2: ZBRA UW Equity | NL2: ZBH UN Equity | NM2: CPT UN Equity | NN2: CBRE UN Equity | NO2: MA UN Equity | NP2: DDOG UW Equity | NQ2: ICE UN Equity | NR2: FIS UN Equity | NS2: CMG UN Equity | NT2: WYNN UW Equity | NU2: LYV UN Equity | NV2: AIZ UN Equity | NW2: NRG UN Equity | NX2: MNST UW Equity | NY2: RF UN Equity | NZ2: MOS UN Equity | OA2: EXPE UW Equity | OB2: CF UN Equity | OC2: LDOS UN Equity | OD2: GOOG UW Equity | OE2: TKO UN Equity | OF2: FSLR UW Equity | OG2: V UN Equity | OH2: MAA UN Equity | OI2: XYL UN Equity | OJ2: MPC UN Equity | OK2: TSCO UW Equity | OL2: AMD UW Equity | OM2: RMD UN Equity | ON2: MTD UN Equity | OO2: VICI UN Equity | OP2: CPRT UW Equity | OQ2: J UN Equity | OR2: ALB UN Equity | OS2: FTNT UW Equity | OT2: MRNA UW Equity | OU2: ESS UN Equity | OV2: CSGP UW Equity | OW2: O UN Equity | OX2: WAB UN Equity | OY2: POOL UW Equity | OZ2: WDC UW Equity | PA2: PEP UW Equity | PB2: TEL UN Equity | PC2: FANG UW Equity | PD2: NOW UN Equity | PE2: CHD UN Equity | PF2: FRT UN Equity | PG2: MGM UN Equity | PH2: INVH UN Equity | PI2: PTC UW Equity | PJ2: JBHT UW Equity | PK2: LRCX UW Equity | PL2: MHK UN Equity | PM2: PNR UN Equity | PN2: VRTX UW Equity | PO2: AMCR UN Equity | PP2: META UW Equity | PQ2: TMUS UW Equity | PR2: URI UN Equity | PS2: ARE UN Equity | PT2: DAL UN Equity | PU2: UAL UW Equity | PV2: STX UW Equity | PW2: NWS UW Equity | PX2: CNC UN Equity | PY2: XYZ UN Equity | PZ2: APO UN Equity | QA2: MLM UN Equity | QB2: TER UW Equity | QC2: PYPL UW Equity | QD2: TSLA UW Equity | QE2: BLK UN Equity | QF2: KKR UN Equity | QG2: ACGL UW Equity | QH2: DOW UN Equity | QI2: EG UN Equity | QJ2: TDY UN Equity | QK2: NWSA UW Equity | QL2: EXC UW Equity | QM2: GPN UN Equity | QN2: CCI UN Equity | QO2: ALGN UW Equity | QP2: TRGP UN Equity | QQ2: BG UN Equity | QR2: LKQ UW Equity | QS2: DECK UN Equity | QT2: WDAY UW Equity | QU2: ZTS UN Equity | QV2: EQIX UW Equity | QW2: DLR UN Equity | QX2: MOH UN Equity | QY2: LVS UN Equity | QZ2: SOLV UN Equity | RA2: SMCI UW Equity | RB2: LIN UW Equity | RC2: CARR UN Equity | RD2: OTIS UN Equity | RE2: ABNB UW Equity | RF2: EXE UW Equity | RG2: DASH UW Equity | RH2: VLTO UN Equity | RI2: COO UW Equity | RJ2: CEG UW Equity | RK2: APP UW Equity | RL2: KDP UW Equity | RM2: HST UW Equity | RN2: CPB UW Equity | RO2: EVRG UW Equity | RP2: MTCH UW Equity | RQ2: WBD UW Equity | RR2: ROP UW Equity | RS2: SW UN Equity | RT2: BKR UW Equity | RU2: APA UW Equity | RV2: PLTR UW Equity | RW2: PANW UW Equity | RX2: AEP UW Equity | RY2: GEHC UW Equity | RZ2: HON UW Equity | SA2: HOOD UW Equity | SB2: DPZ UW Equity | SC2: GEV UN Equity | SD2: KVUE UN Equity | SE2: COIN UW Equity
A3: Date | B3: 45657 | C3: 74.27 | D3: 296.79 | E3: 39.99 | F3: 1105.96 | G3: 231.84 | H3: 177 | I3: 362.76 | J3: 239.71 | K3: 144.84 | L3: 62.26 | M3: 177.7 | N3: 111.35 | O3: 338.42 | P3: 149.6 | Q3: 107.57 | R3: 113.93 | S3: 166.79 | T3: 32.63 | U3: 388.99 | V3: 591.7 | W3: 219.83 | X3: 144.62 | Y3: 382.41 | Z3: 289.89 | AA3: 99.48 | AB3: 129.09 | AC3: 124.49 | AD3: 43.95 | AE3: 26.53 | AF3: 167.65 | AG3: 22.77 | AH3: 240.89 | AI3: 115.72 | AJ3: 212.46 | AK3: 90.35 | AL3: 59.2 | AM3: 20.05 | AN3: 53.27 | AO3: 421.5 | AP3: 75.82 | AQ3: 276.14 | AR3: 27.4 | AS3: 70.39 | AT3: 72.8 | AU3: 52.29 | AV3: 300.15 | AW3: 53.82 | AX3: 21.35 | AY3: 113.11 | AZ3: 103.44 | BA3: 290.04 | BB3: 230.69 | BC3: 44.1675 | BD3: 609.3 | BE3: 50.52 | BF3: 453.9 | BG3: 292.73 | BH3: 275.43 | BI3: 3202 | BJ3: 187.13 | BK3: 600.01 | BL3: 55.13 | BM3: 594.32 | BN3: 72.64 | BO3: 76.83 | BP3: 29.16 | BQ3: 226.87 | BR3: 453.28 | BS3: 85.8 | BT3: 89.32 | BU3: 56.56 | BV3: 37.98 | BW3: 25.54 | BX3: 247.16 | BY3: 24.92 | BZ3: 142.93 | CA3: 43.41 | CB3: 162.41 | CC3: 204.97 | CD3: 66.65 | CE3: 90.91 | CF3: 233.82 | CG3: 27.75 | CH3: 89.23 | CI3: 47.52 | CJ3: 197.37 | CK3: 348.6 | CL3: 229.55 | CM3: 135.18 | CN3: 185.18 | CO3: 423.7 | CP3: 53.86 | CQ3: 117.53 | CR3: 187.6 | CS3: 59.14 | CT3: 114.07 | CU3: 107.74 | CV3: 73.93 | CW3: 331.87 | CX3: 234.32 | CY3: 111.61 | CZ3: 115.24 | DA3: 123.93 | DB3: 122.58 | DC3: 359.16 | DD3: 75.82 | DE3: 254.85 | DF3: 46.11 | DG3: 196.51 | DH3: 484.47 | DI3: 281.33 | DJ3: 102.02 | DK3: 9.9 | DL3: 71.69 | DM3: 20.29 | DN3: 206.26 | DO3: 38.08 | DP3: 77.77 | DQ3: 263.49 | DR3: 63.77 | DS3: 116.76 | DT3: 139.27 | DU3: 1054.05 | DV3: 27.19 | DW3: 210.28 | DX3: 20.27 | DY3: 261.07 | DZ3: 56.5014 | EA3: 169.35 | EB3: 65 | EC3: 31.37 | ED3: 283.85 | EE3: 59.73 | EF3: 31.73 | EG3: 253.71 | EH3: 313.24 | EI3: 253.56 | EJ3: 174.04 | EK3: 369.35 | EL3: 84.55 | EM3: 155.05 | EN3: 207.85 | EO3: 80.97 | EP3: 226.09 | EQ3: 23.43 | ER3: 166.64 | ES3: 61.15 | ET3: 136.37 | EU3: 772 | EV3: 342.77 | EW3: 84.69 | EX3: 246.8 | EY3: 418.89 | EZ3: 209.29 | FA3: 212.41 | FB3: 72.57 | FC3: 498.03 | FD3: 79.88 | FE3: 12.45 | FF3: 44.89 | FG3: 31.8915 | FH3: 84.16 | FI3: 462.23 | FJ3: 195.4 | FK3: 37.22 | FL3: 75.67 | FM3: 36.76 | FN3: 234.7 | FO3: 77.41 | FP3: 57.43 | FQ3: 469.29 | FR3: 70.24 | FS3: 116.71 | FT3: 49.41 | FU3: 86.04 | FV3: 100.4 | FW3: 155.33 | FX3: 20.18 | FY3: 636.03 | FZ3: 46.35 | GA3: 32.46 | GB3: 60.48 | GC3: 99.17 | GD3: 108.9 | GE3: 84.77 | GF3: 192.85 | GG3: 119.45 | GH3: 239.61 | GI3: 84.49 | GJ3: 79.84 | GK3: 38.34 | GL3: 74.01 | GM3: 339.93 | GN3: 327.56 | GO3: 110.12 | GP3: 339.48 | GQ3: 180.26 | GR3: 60.32 | GS3: 82.32 | GT3: 43.38 | GU3: 33.62 | GV3: 58.52 | GW3: 80.29 | GX3: 299.44 | GY3: 110.53 | GZ3: 76.46 | HA3: 56.96 | HB3: 187.51 | HC3: 76.49 | HD3: 520.23 | HE3: 120.81 | HF3: 111.52 | HG3: 78.93 | HH3: 434.93 | HI3: 228.04 | HJ3: 160.63 | HK3: 505.86 | HL3: 172.42 | HM3: 58.89 | HN3: 229.32 | HO3: 257.23 | HP3: 28.15 | HQ3: 54.12 | HR3: 94.04 | HS3: 444.68 | HT3: 137.87 | HU3: 12.87 | HV3: 110.77 | HW3: 260.64 | HX3: 250.42 | HY3: 295.57 | HZ3: 182.7 | IA3: 37.53 | IB3: 57.32 | IC3: 630.12 | ID3: 278.94 | IE3: 76.24 | IF3: 104.02 | IG3: 916.27 | IH3: 360.05 | II3: 57.44 | IJ3: 66.83 | IK3: 162.63 | IL3: 118.27 | IM3: 143.7 | IN3: 139.82 | IO3: 146.3 | IP3: 412.23 | IQ3: 1990.93 | IR3: 35.955 | IS3: 188.01 | IT3: 67.52 | IU3: 42.28 | IV3: 92.37 | IW3: 55.91 | IX3: 16.27 | IY3: 126.03 | IZ3: 152.92 | JA3: 102.5 | JB3: 225.13 | JC3: 140.22 | JD3: 153.62 | JE3: 151.27 | JF3: 413.44 | JG3: 91.25 | JH3: 17.14 | JI3: 48.58 | JJ3: 45.74 | JK3: 98.15 | JL3: 25.73 | JM3: 47.83 | JN3: 68.21 | JO3: 27.38 | JP3: 113.09 | JQ3: 201.79 | JR3: 221 | JS3: 17.48 | JT3: 628.5 | JU3: 125.72 | JV3: 57.35 | JW3: 342.16 | JX3: 276.3 | JY3: 72.09 | JZ3: 43.76 | KA3: 143.9 | KB3: 79.053 | KC3: 192.79 | KD3: 71.76 | KE3: 69.07 | KF3: 172.21 | KG3: 219.97 | KH3: 118.53 | KI3: 126.1 | KJ3: 205.56 | KK3: 569.91 | KL3: 485.94 | KM3: 224.68 | KN3: 178.32 | KO3: 370.98 | KP3: 209.24 | KQ3: 74.94 | KR3: 186.69 | KS3: 8178.9 | KT3: 116.08 | KU3: 176.4 | KV3: 149.55 | KW3: 109.4 | KX3: 105.11 | KY3: 74.98 | KZ3: 300.46 | LA3: 576.64 | LB3: 179.42 | LC3: 88.68 | LD3: 150.86 | LE3: 285.79 | LF3: 30.71 | LG3: 183.41 | LH3: 712.33 | LI3: 219.39 | LJ3: 175.3 | LK3: 230.98 | LL3: 74.36 | LM3: 69.45 | LN3: 109.37 | LO3: 122.59 | LP3: 485.36 | LQ3: 103.32 | LR3: 351.79 | LS3: 1267.28 | LT3: 134.16 | LU3: 105.7 | LV3: 39.78 | LW3: 206.96 | LX3: 316.05 | LY3: 69.2 | LZ3: 89.14 | MA3: 480.28 | MB3: 134.29 | MC3: 76.9 | MD3: 521.96 | ME3: 184.08 | MF3: 201.18 | MG3: 61.95 | MH3: 572.62 | MI3: 203.8 | MJ3: 87.72 | MK3: 473.37 | ML3: 63.05 | MM3: 4968.42 | MN3: 251.47 | MO3: 95.65 | MP3: 184.6 | MQ3: 32.73 | MR3: 72.03 | MS3: 189.3 | MT3: 130.68 | MU3: 89.132 | MV3: 134.34 | MW3: 70.66 | MX3: 368.9 | MY3: 232.23 | MZ3: 120.75 | NA3: 77.31 | NB3: 120.35 | NC3: 90.46 | ND3: 334.33 | NE3: 188.97 | NF3: 81.88 | NG3: 65.33 | NH3: 32.27 | NI3: 74.03 | NJ3: 532.43 | NK3: 386.22 | NL3: 105.63 | NM3: 116.04 | NN3: 131.29 | NO3: 526.57 | NP3: 142.89 | NQ3: 149.01 | NR3: 80.77 | NS3: 60.3 | NT3: 86.16 | NU3: 129.5 | NV3: 213.22 | NW3: 90.22 | NX3: 52.56 | NY3: 23.52 | NZ3: 24.58 | OA3: 186.33 | OB3: 85.32 | OC3: 144.06 | OD3: 190.44 | OE3: 142.11 | OF3: 176.24 | OG3: 316.04 | OH3: 154.57 | OI3: 116.02 | OJ3: 139.5 | OK3: 53.06 | OL3: 120.79 | OM3: 228.69 | ON3: 1223.68 | OO3: 29.21 | OP3: 57.39 | OQ3: 132.2568 | OR3: 86.08 | OS3: 94.48 | OT3: 41.58 | OU3: 285.44 | OV3: 71.59 | OW3: 53.41 | OX3: 189.59 | OY3: 340.94 | OZ3: 45.0579 | PA3: 152.06 | PB3: 142.97 | PC3: 163.83 | PD3: 1060.12 | PE3: 104.71 | PF3: 111.95 | PG3: 34.65 | PH3: 31.97 | PI3: 183.87 | PJ3: 170.66 | PK3: 72.23 | PL3: 119.13 | PM3: 100.64 | PN3: 402.7 | PO3: 9.41 | PP3: 585.51 | PQ3: 220.73 | PR3: 704.44 | PS3: 97.55 | PT3: 60.5 | PU3: 97.1 | PV3: 86.31 | PW3: 30.43 | PX3: 60.58 | PY3: 84.99 | PZ3: 165.16 | QA3: 516.5 | QB3: 125.92 | QC3: 85.35 | QD3: 403.84 | QE3: 1025.11 | QF3: 147.91 | QG3: 92.35 | QH3: 40.13 | QI3: 362.46 | QJ3: 464.13 | QK3: 27.54 | QL3: 37.64 | QM3: 112.06 | QN3: 90.76 | QO3: 208.51 | QP3: 178.5 | QQ3: 77.76 | QR3: 36.75 | QS3: 203.09 | QT3: 258.03 | QU3: 162.93 | QV3: 942.89 | QW3: 177.33 | QX3: 291.05 | QY3: 51.36 | QZ3: 66.06 | RA3: 30.48 | RB3: 418.67 | RC3: 68.26 | RD3: 92.61 | RE3: 131.41 | RF3: 99.55 | RG3: 167.75 | RH3: 101.85 | RI3: 91.93 | RJ3: 223.71 | RK3: 323.83 | RL3: 32.12 | RM3: 17.52 | RN3: 41.88 | RO3: 61.55 | RP3: 32.71 | RQ3: 10.57 | RR3: 519.85 | RS3: 53.86 | RT3: 41.02 | RU3: 23.09 | RV3: 75.63 | RW3: 181.96 | RX3: 92.23 | RY3: 78.18 | RZ3: 212.8257 | SA3: 37.26 | SB3: 419 | SC3: 328.93 | SD3: 21.35 | SE3: 248.3
B4: 45660 | C4: 72.77 | D4: 303.08 | E4: 40.26 | F4: 1211.03 | G4: 232.55 | H4: 169.9 | I4: 363.79 | J4: 243.28 | K4: 147.85 | L4: 61.75 | M4: 181.22 | N4: 111.16 | O4: 341.85 | P4: 151.04 | Q4: 107.86 | R4: 116.09 | S4: 171.96 | T4: 33.14 | U4: 389.18 | V4: 619.87 | W4: 222.65 | X4: 144.19 | Y4: 378.18 | Z4: 294.78 | AA4: 99.14 | AB4: 129.87 | AC4: 123.77 | AD4: 44.81 | AE4: 26.59 | AF4: 165.13 | AG4: 22.67 | AH4: 242.29 | AI4: 115.87 | AJ4: 215.37 | AK4: 90.78 | AL4: 58.86 | AM4: 20.56 | AN4: 51.77 | AO4: 423.35 | AP4: 74.67 | AQ4: 280.7 | AR4: 28.27 | AS4: 71 | AT4: 72.81 | AU4: 53.14 | AV4: 296.7 | AW4: 52.85 | AX4: 21.82 | AY4: 113.83 | AZ4: 103.16 | BA4: 283.91 | BB4: 228.94 | BC4: 45.93 | BD4: 612.71 | BE4: 50.05 | BF4: 473.65 | BG4: 291.69 | BH4: 276.28 | BI4: 3268.78 | BJ4: 185.09 | BK4: 601.48 | BL4: 54.03 | BM4: 601.06 | BN4: 72.52 | BO4: 76.93 | BP4: 29.5 | BQ4: 228.46 | BR4: 453.56 | BS4: 83.62 | BT4: 90.69 | BU4: 56.57 | BV4: 36.25 | BW4: 26.24 | BX4: 246.52 | BY4: 24.38 | BZ4: 144.03 | CA4: 43.08 | CB4: 162.89 | CC4: 203.86 | CD4: 66.61 | CE4: 90.15 | CF4: 230.72 | CG4: 27.65 | CH4: 89.24 | CI4: 47.5 | CJ4: 200.39 | CK4: 354.35 | CL4: 234.84 | CM4: 135.79 | CN4: 192.7 | CO4: 422.22 | CP4: 54.73 | CQ4: 121.84 | CR4: 188.03 | CS4: 58.34 | CT4: 113.15 | CU4: 107.78 | CV4: 73.03 | CW4: 342.58 | CX4: 231.93 | CY4: 113.6 | CZ4: 119.91 | DA4: 123.44 | DB4: 126.57 | DC4: 353.98 | DD4: 76.68 | DE4: 253.39 | DF4: 47.02 | DG4: 197.39 | DH4: 485.97 | DI4: 274.41 | DJ4: 101.59 | DK4: 9.88 | DL4: 71.99 | DM4: 20.41 | DN4: 207.15 | DO4: 37.71 | DP4: 81.07 | DQ4: 263.37 | DR4: 63.88 | DS4: 116.86 | DT4: 138.79 | DU4: 1053.99 | DV4: 27.68 | DW4: 209.75 | DX4: 20.42 | DY4: 266.3 | DZ4: 57.1794 | EA4: 169.03 | EB4: 66.78 | EC4: 31.36 | ED4: 280.4 | EE4: 59.86 | EF4: 31.64 | EG4: 262.47 | EH4: 309.04 | EI4: 252.29 | EJ4: 174.23 | EK4: 381.11 | EL4: 82.52 | EM4: 158.88 | EN4: 208.86 | EO4: 81.21 | EP4: 229.23 | EQ4: 23.17 | ER4: 166.32 | ES4: 61.46 | ET4: 135.88 | EU4: 781.98 | EV4: 358.35 | EW4: 84.35 | EX4: 248.48 | EY4: 430.96 | EZ4: 207.02 | FA4: 211.27 | FB4: 72.2 | FC4: 499.57 | FD4: 80.95 | FE4: 12.28 | FF4: 45.77 | FG4: 31.2641 | FH4: 89.87 | FI4: 461.84 | FJ4: 195.24 | FK4: 38.11 | FL4: 73.31 | FM4: 36.39 | FN4: 235.88 | FO4: 77.91 | FP4: 57.31 | FQ4: 467.82 | FR4: 71.31 | FS4: 115.45 | FT4: 50.51 | FU4: 85.89 | FV4: 102.9 | FW4: 157.72 | FX4: 20.4 | FY4: 637.68 | FZ4: 46.17 | GA4: 32.27 | GB4: 60.53 | GC4: 101.09 | GD4: 110.05 | GE4: 84.25 | GF4: 195.63 | GG4: 114.27 | GH4: 242.22 | GI4: 86.25 | GJ4: 79.8 | GK4: 38.59 | GL4: 74.45 | GM4: 336.54 | GN4: 335.56 | GO4: 111.53 | GP4: 336.07 | GQ4: 179.57 | GR4: 64.59 | GS4: 82.32 | GT4: 44.1 | GU4: 33.61 | GV4: 57.93 | GW4: 80.76 | GX4: 300.45 | GY4: 115.2 | GZ4: 75.43 | HA4: 55.94 | HB4: 190.51 | HC4: 75.73 | HD4: 532.02 | HE4: 120.73 | HF4: 111.51 | HG4: 79.92 | HH4: 431.35 | HI4: 231.5 | HJ4: 163.8 | HK4: 513 | HL4: 175.91 | HM4: 58.31 | HN4: 229.15 | HO4: 257.13 | HP4: 28.36 | HQ4: 56.6 | HR4: 93.79 | HS4: 430.57 | HT4: 162.36 | HU4: 13.23 | HV4: 111.28 | HW4: 261.22 | HX4: 243.36 | HY4: 294.06 | HZ4: 185.85 | IA4: 37.67 | IB4: 55.27 | IC4: 657.01 | ID4: 275.28 | IE4: 75.85 | IF4: 104.9 | IG4: 916.58 | IH4: 361.52 | II4: 58.18 | IJ4: 65.53 | IK4: 170.06 | IL4: 119.3 | IM4: 142.1 | IN4: 139.89 | IO4: 146.29 | IP4: 414.7 | IQ4: 1966.26 | IR4: 35.845 | IS4: 191.54 | IT4: 66.69 | IU4: 42.39 | IV4: 91.41 | IW4: 56.8 | IX4: 16.45 | IY4: 125.82 | IZ4: 152.21 | JA4: 103.28 | JB4: 225.88 | JC4: 139.67 | JD4: 157.83 | JE4: 154.25 | JF4: 415.53 | JG4: 92.58 | JH4: 17.29 | JI4: 49.32 | JJ4: 46.72 | JK4: 97.67 | JL4: 25.42 | JM4: 48.86 | JN4: 68.6 | JO4: 27.5 | JP4: 114.69 | JQ4: 201.65 | JR4: 221.92 | JS4: 17.75 | JT4: 630.23 | JU4: 125.94 | JV4: 57.67 | JW4: 359.02 | JX4: 271.73 | JY4: 73.19 | JZ4: 44.56 | KA4: 149.66 | KB4: 80.281 | KC4: 191.45 | KD4: 70.9 | KE4: 69.63 | KF4: 176.07 | KG4: 219.17 | KH4: 119.14 | KI4: 123.79 | KJ4: 204.12 | KK4: 577.44 | KL4: 481.82 | KM4: 229.2 | KN4: 180.43 | KO4: 371.76 | KP4: 207.56 | KQ4: 73.36 | KR4: 187.72 | KS4: 8070.6 | KT4: 116.94 | KU4: 180.91 | KV4: 152.82 | KW4: 109.5 | KX4: 105.7 | KY4: 72.16 | KZ4: 303.86 | LA4: 584.17 | LB4: 178.89 | LC4: 88.85 | LD4: 151.92 | LE4: 282.79 | LF4: 30.61 | LG4: 182.56 | LH4: 718.15 | LI4: 224.19 | LJ4: 173.7 | LK4: 234.49 | LL4: 74.91 | LM4: 70.1 | LN4: 112.76 | LO4: 124.26 | LP4: 493.71 | LQ4: 104.44 | LR4: 353.85 | LS4: 1275.56 | LT4: 133.44 | LU4: 105.63 | LV4: 39.92 | LW4: 205.62 | LX4: 326.52 | LY4: 69.09 | LZ4: 88.85 | MA4: 475.06 | MB4: 144.47 | MC4: 76.38 | MD4: 535.295 | ME4: 188.75 | MF4: 201.04 | MG4: 61.61 | MH4: 580.13 | MI4: 201.8 | MJ4: 87.67 | MK4: 479.15 | ML4: 63.91 | MM4: 4903.85 | MN4: 254.36 | MO4: 93.56 | MP4: 185.8 | MQ4: 33.93 | MR4: 73.79 | MS4: 191.79 | MT4: 130.18 | MU4: 88.105 | MV4: 135.69 | MW4: 70.57 | MX4: 371.56 | MY4: 232.5 | MZ4: 121.58 | NA4: 78.22 | NB4: 122.02 | NC4: 92.49 | ND4: 332.9 | NE4: 188.08 | NF4: 82.21 | NG4: 66.77 | NH4: 32.34 | NI4: 73.91 | NJ4: 535.84 | NK4: 391.86 | NL4: 104.47 | NM4: 117.07 | NN4: 131.5 | NO4: 521.36 | NP4: 144.83 | NQ4: 149.84 | NR4: 80.26 | NS4: 59.7 | NT4: 83.32 | NU4: 129.49 | NV4: 211.85 | NW4: 98.5 | NX4: 52.39 | NY4: 23.62 | NZ4: 25.15 | OA4: 186.09 | OB4: 88.51 | OC4: 147.15 | OD4: 193.13 | OE4: 142.4 | OF4: 186.43 | OG4: 314.91 | OH4: 155.06 | OI4: 117.18 | OJ4: 142.74 | OK4: 51.93 | OL4: 125.37 | OM4: 231.67 | ON4: 1238.28 | OO4: 29.46 | OP4: 56.91 | OQ4: 132.435 | OR4: 87.79 | OS4: 97.47 | OT4: 42.18 | OU4: 284.25 | OV4: 72.25 | OW4: 53.28 | OX4: 190.45 | OY4: 337.27 | OZ4: 48.4128 | PA4: 149.65 | PB4: 142.4 | PC4: 170.96 | PD4: 1073.77 | PE4: 104.64 | PF4: 109.63 | PG4: 34.09 | PH4: 31.93 | PI4: 184.54 | PJ4: 175.82 | PK4: 75.11 | PL4: 117.31 | PM4: 101.06 | PN4: 407.11 | PO4: 9.33 | PP4: 604.63 | PQ4: 219.11 | PR4: 695.31 | PS4: 99.16 | PT4: 59 | PU4: 95.67 | PV4: 89.15 | PW4: 30.5 | PX4: 61.48 | PY4: 92.16 | PZ4: 169.06 | QA4: 516.67 | QB4: 130.6 | QC4: 87.6 | QD4: 410.44 | QE4: 1020.83 | QF4: 152.03 | QG4: 91.4 | QH4: 39.4 | QI4: 365.14 | QJ4: 459.7 | QK4: 27.55 | QL4: 38.05 | QM4: 112.58 | QN4: 89.99 | QO4: 208.26 | QP4: 186.17 | QQ4: 77.28 | QR4: 36.59 | QS4: 207.25 | QT4: 252.84 | QU4: 163.31 | QV4: 959.97 | QW4: 181.74 | QX4: 294.49 | QY4: 50.42 | QZ4: 67.12 | RA4: 33.33 | RB4: 413.5 | RC4: 69.26 | RD4: 92.89 | RE4: 135.71 | RF4: 100.01 | RG4: 174.96 | RH4: 100.8 | RI4: 91.79 | RJ4: 252.4 | RK4: 350.65 | RL4: 31.54 | RM4: 17.45 | RN4: 41.74 | RO4: 61.55 | RP4: 32.68 | RQ4: 10.57 | RR4: 514.64 | RS4: 52.3 | RT4: 42.66 | RU4: 23.42 | RV4: 79.89 | RW4: 183.25 | RX4: 92.05 | RY4: 80.52 | RZ4: 213.4192 | SA4: 41.35 | SB4: 438.08 | SC4: 354.03 | SD4: 21.2 | SE4: 270.65
B5: 45664 | C5: 73.9 | D5: 302.02 | E5: 38.92 | F5: 1258.29 | G5: 228.64 | H5: 172.51 | I5: 363 | J5: 243.17 | K5: 149.59 | L5: 60.84 | M5: 179.53 | N5: 111.39 | O5: 347.63 | P5: 148.43 | Q5: 108.75 | R5: 115.19 | S5: 172.31 | T5: 33.67 | U5: 384.23 | V5: 624.87 | W5: 223.96 | X5: 146.23 | Y5: 393.46 | Z5: 289.34 | AA5: 101.02 | AB5: 132.77 | AC5: 121.63 | AD5: 46.08 | AE5: 27.13 | AF5: 161.3 | AG5: 22.2 | AH5: 241.68 | AI5: 114.8 | AJ5: 215.87 | AK5: 90.81 | AL5: 58.93 | AM5: 20.01 | AN5: 51.98 | AO5: 422.37 | AP5: 74.17 | AQ5: 279.93 | AR5: 27.81 | AS5: 73.68 | AT5: 72.59 | AU5: 51.46 | AV5: 308.21 | AW5: 53.61 | AX5: 22.28 | AY5: 113.4 | AZ5: 102.84 | BA5: 286.33 | BB5: 225.33 | BC5: 47.7925 | BD5: 611.29 | BE5: 49.43 | BF5: 470.18 | BG5: 288.4 | BH5: 273.52 | BI5: 3259.91 | BJ5: 186.69 | BK5: 591.33 | BL5: 53.69 | BM5: 562.03 | BN5: 71.23 | BO5: 77.96 | BP5: 29.58 | BQ5: 232.15 | BR5: 452.92 | BS5: 84.28 | BT5: 91.99 | BU5: 57.14 | BV5: 36.23 | BW5: 26.36 | BX5: 241.38 | BY5: 23.84 | BZ5: 143.32 | CA5: 41.07 | CB5: 159.7 | CC5: 202.1 | CD5: 65.71 | CE5: 87.39 | CF5: 228.45 | CG5: 26.63 | CH5: 88 | CI5: 47.85 | CJ5: 195.57 | CK5: 359.98 | CL5: 239.1 | CM5: 139.25 | CN5: 195.37 | CO5: 413.27 | CP5: 54.03 | CQ5: 121.41 | CR5: 187.98 | CS5: 57.36 | CT5: 119.81 | CU5: 106.81 | CV5: 70.16 | CW5: 343.91 | CX5: 231.44 | CY5: 116.6 | CZ5: 121.27 | DA5: 120.68 | DB5: 127.56 | DC5: 348.44 | DD5: 75.96 | DE5: 245.5 | DF5: 48.15 | DG5: 202.65 | DH5: 491.48 | DI5: 275 | DJ5: 101.07 | DK5: 9.76 | DL5: 70.43 | DM5: 19.74 | DN5: 208.55 | DO5: 38.74 | DP5: 79.35 | DQ5: 259.65 | DR5: 60.89 | DS5: 116.61 | DT5: 136.63 | DU5: 1062.75 | DV5: 27.75 | DW5: 203 | DX5: 19.91 | DY5: 265.65 | DZ5: 57.7444 | EA5: 165.52 | EB5: 66.58 | EC5: 30.14 | ED5: 279.77 | EE5: 58.29 | EF5: 30.87 | EG5: 267.21 | EH5: 309 | EI5: 248.59 | EJ5: 180.98 | EK5: 379.96 | EL5: 82.56 | EM5: 161 | EN5: 212.58 | EO5: 81.35 | EP5: 226.32 | EQ5: 21.97 | ER5: 162.03 | ES5: 59.14 | ET5: 133.14 | EU5: 773.29 | EV5: 347.63 | EW5: 82.95 | EX5: 246.57 | EY5: 433.96 | EZ5: 208 | FA5: 209.98 | FB5: 71.7 | FC5: 491.35 | FD5: 79.87 | FE5: 12 | FF5: 45.78 | FG5: 31.4021 | FH5: 101.91 | FI5: 455.15 | FJ5: 190.84 | FK5: 38.16 | FL5: 72.09 | FM5: 35.77 | FN5: 237.76 | FO5: 78.3 | FP5: 56.08 | FQ5: 452.39 | FR5: 71.59 | FS5: 121.28 | FT5: 51.55 | FU5: 84.63 | FV5: 101.61 | FW5: 158.98 | FX5: 19.98 | FY5: 635.23 | FZ5: 45.75 | GA5: 32 | GB5: 61.82 | GC5: 101.67 | GD5: 107.83 | GE5: 83.2 | GF5: 194.77 | GG5: 115.86 | GH5: 242.28 | GI5: 85.41 | GJ5: 77.38 | GK5: 39.37 | GL5: 72.26 | GM5: 334.4 | GN5: 332.53 | GO5: 107.47 | GP5: 335.66 | GQ5: 178.69 | GR5: 66.15 | GS5: 81.09 | GT5: 43.97 | GU5: 32.88 | GV5: 57.5 | GW5: 81.65 | GX5: 298.2 | GY5: 115.29 | GZ5: 74.55 | HA5: 57.03 | HB5: 192.21 | HC5: 75.6 | HD5: 545.65 | HE5: 120.14 | HF5: 111.49 | HG5: 79.17 | HH5: 428.27 | HI5: 230.54 | HJ5: 166.13 | HK5: 514.25 | HL5: 171.34 | HM5: 57.07 | HN5: 235.1 | HO5: 251.98 | HP5: 28.01 | HQ5: 55.55 | HR5: 93.19 | HS5: 422.63 | HT5: 163.37 | HU5: 12.95 | HV5: 111.4 | HW5: 262.06 | HX5: 242.21 | HY5: 290.82 | HZ5: 188.72 | IA5: 37.18 | IB5: 55.19 | IC5: 689.3 | ID5: 269.78 | IE5: 74.32 | IF5: 109.56 | IG5: 921.37 | IH5: 355.18 | II5: 55.58 | IJ5: 61.68 | IK5: 177.82 | IL5: 121.4 | IM5: 142.31 | IN5: 137.84 | IO5: 144.67 | IP5: 402.26 | IQ5: 1935.16 | IR5: 36.155 | IS5: 192.04 | IT5: 65.64 | IU5: 42.86 | IV5: 90.63 | IW5: 57.11 | IX5: 16.55 | IY5: 124.24 | IZ5: 153.15 | JA5: 102.75 | JB5: 225.98 | JC5: 139.26 | JD5: 160.52 | JE5: 151.56 | JF5: 427.26 | JG5: 92.84 | JH5: 17.19 | JI5: 49.23 | JJ5: 46.81 | JK5: 97.72 | JL5: 25.51 | JM5: 48.7 | JN5: 68.3 | JO5: 26.98 | JP5: 113.12 | JQ5: 203.39 | JR5: 218.51 | JS5: 17.15 | JT5: 615.43 | JU5: 126.88 | JV5: 57.47 | JW5: 359.93 | JX5: 268.76 | JY5: 72.69 | JZ5: 44.7 | KA5: 152.73 | KB5: 79.981 | KC5: 186.04 | KD5: 67.45 | KE5: 73.19 | KF5: 174.17 | KG5: 211.23 | KH5: 119.18 | KI5: 124.98 | KJ5: 206.49 | KK5: 585.24 | KL5: 463.96 | KM5: 234.24 | KN5: 181.89 | KO5: 377.03 | KP5: 205.43 | KQ5: 75.01 | KR5: 184.34 | KS5: 7897 | KT5: 117.18 | KU5: 180.64 | KV5: 152.69 | KW5: 109.02 | KX5: 100.69 | KY5: 74.17 | KZ5: 301.67 | LA5: 563.54 | LB5: 186 | LC5: 92.66 | LD5: 153.64 | LE5: 281.31 | LF5: 29.77 | LG5: 177.17 | LH5: 730.3 | LI5: 222.11 | LJ5: 171.34 | LK5: 242.52 | LL5: 70.33 | LM5: 71.46 | LN5: 111.66 | LO5: 123.99 | LP5: 487.62 | LQ5: 104.05 | LR5: 356.39 | LS5: 1252.13 | LT5: 128.55 | LU5: 106.58 | LV5: 39.31 | LW5: 209.22 | LX5: 319.81 | LY5: 71.67 | LZ5: 87.96 | MA5: 460.68 | MB5: 140.14 | MC5: 75.62 | MD5: 531.88 | ME5: 181.75 | MF5: 203.05 | MG5: 63.17 | MH5: 580.12 | MI5: 195.89 | MJ5: 84.23 | MK5: 464 | ML5: 62.73 | MM5: 4796.1 | MN5: 257.29 | MO5: 92.54 | MP5: 189.76 | MQ5: 34.69 | MR5: 74.77 | MS5: 195.49 | MT5: 127.42 | MU5: 87.919 | MV5: 137.41 | MW5: 72.02 | MX5: 380.75 | MY5: 227.01 | MZ5: 120.38 | NA5: 76.36 | NB5: 121.4 | NC5: 89.16 | ND5: 324.93 | NE5: 189.05 | NF5: 82.14 | NG5: 67.36 | NH5: 32.19 | NI5: 73.64 | NJ5: 528.83 | NK5: 396.11 | NL5: 103.13 | NM5: 110.31 | NN5: 128.64 | NO5: 511.4 | NP5: 141.4 | NQ5: 146.44 | NR5: 79.16 | NS5: 57.99 | NT5: 82.45 | NU5: 129.64 | NV5: 207 | NW5: 96.73 | NX5: 51.55 | NY5: 23.85 | NZ5: 25.25 | OA5: 182.33 | OB5: 88.75 | OC5: 147.3 | OD5: 196.71 | OE5: 141.81 | OF5: 197.73 | OG5: 311.67 | OH5: 148.26 | OI5: 115.78 | OJ5: 141.66 | OK5: 53.87 | OL5: 127.33 | OM5: 236.4 | ON5: 1254.99 | OO5: 29.25 | OP5: 56.24 | OQ5: 130.5049 | OR5: 89.98 | OS5: 95.93 | OT5: 47.53 | OU5: 270.06 | OV5: 70.36 | OW5: 52.51 | OX5: 189.14 | OY5: 327.97 | OZ5: 49.0173 | PA5: 145.4 | PB5: 143.76 | PC5: 172.42 | PD5: 1054.15 | PE5: 102.8 | PF5: 104.9 | PG5: 33.23 | PH5: 30.96 | PI5: 183.09 | PJ5: 176.48 | PK5: 77.52 | PL5: 117.3 | PM5: 98.68 | PN5: 408.32 | PO5: 9.5 | PP5: 617.89 | PQ5: 212.335 | PR5: 685.41 | PS5: 97.36 | PT5: 61.18 | PU5: 101.21 | PV5: 89.6 | PW5: 30.46 | PX5: 62.61 | PY5: 87.68 | PZ5: 162.45 | QA5: 508.65 | QB5: 138.82 | QC5: 87.97 | QD5: 394.36 | QE5: 980.76 | QF5: 146.62 | QG5: 92.25 | QH5: 39.41 | QI5: 371.02 | QJ5: 458.78 | QK5: 27.6 | QL5: 37.53 | QM5: 112.28 | QN5: 87.46 | QO5: 217.56 | QP5: 187.82 | QQ5: 77.81 | QR5: 36.49 | QS5: 205.1 | QT5: 249.68 | QU5: 163.49 | QV5: 940.07 | QW5: 179.88 | QX5: 296.48 | QY5: 49.5 | QZ5: 69.41 | RA5: 34.38 | RB5: 414.95 | RC5: 68.21 | RD5: 92.12 | RE5: 131.29 | RF5: 102.68 | RG5: 170 | RH5: 101.65 | RI5: 92.69 | RJ5: 255.63 | RK5: 330.005 | RL5: 30.68 | RM5: 17.05 | RN5: 39.95 | RO5: 60.54 | RP5: 32.4 | RQ5: 10.51 | RR5: 507.1 | RS5: 52.11 | RT5: 43.4 | RU5: 23.66 | RV5: 69.99 | RW5: 175.51 | RX5: 90.47 | RY5: 83.37 | RZ5: 207.8699 | SA5: 40.56 | SB5: 410.9 | SC5: 368.52 | SD5: 21.05 | SE5: 264.33
B6: 45665 | C6: 73.03 | D6: 302.85 | E6: 38.94 | F6: 1275.94 | G6: 229.31 | H6: 171.76 | I6: 361.07 | J6: 243.13 | K6: 150.3 | L6: 61.71 | M6: 178.5 | N6: 109.76 | O6: 357.42 | P6: 148.01 | Q6: 106.93 | R6: 116.25 | S6: 172.89 | T6: 33.45 | U6: 387.2 | V6: 620.96 | W6: 223.18 | X6: 142.27 | Y6: 392.92 | Z6: 286.9 | AA6: 99.85 | AB6: 134.53 | AC6: 122.61 | AD6: 46.21 | AE6: 26.86 | AF6: 162.1 | AG6: 22.18 | AH6: 242.77 | AI6: 115.92 | AJ6: 220.44 | AK6: 91.8 | AL6: 59.2 | AM6: 19.88 | AN6: 51 | AO6: 424.56 | AP6: 71.62 | AQ6: 279.32 | AR6: 28.29 | AS6: 73.26 | AT6: 71.43 | AU6: 51.49 | AV6: 311.25 | AW6: 54.68 | AX6: 22.03 | AY6: 114.25 | AZ6: 103.57 | BA6: 285.25 | BB6: 227.22 | BC6: 47.7225 | BD6: 625.57 | BE6: 49.84 | BF6: 475.86 | BG6: 291.89 | BH6: 280.42 | BI6: 3303.35 | BJ6: 187.71 | BK6: 602.23 | BL6: 53.46 | BM6: 577.34 | BN6: 70.13 | BO6: 77.95 | BP6: 29.59 | BQ6: 234.43 | BR6: 451.84 | BS6: 84.19 | BT6: 95.95 | BU6: 56.81 | BV6: 35.99 | BW6: 27.15 | BX6: 243.3 | BY6: 24.18 | BZ6: 143.5 | CA6: 41.22 | CB6: 160.63 | CC6: 199.42 | CD6: 66.3 | CE6: 87.46 | CF6: 228.51 | CG6: 26.6 | CH6: 89.01 | CI6: 47.73 | CJ6: 197.14 | CK6: 359.75 | CL6: 238.09 | CM6: 138.22 | CN6: 194.59 | CO6: 410 | CP6: 54.6 | CQ6: 121.52 | CR6: 187.22 | CS6: 58.2 | CT6: 116.48 | CU6: 108.23 | CV6: 70.15 | CW6: 345.11 | CX6: 234.57 | CY6: 116.42 | CZ6: 119.31 | DA6: 120.3 | DB6: 128.46 | DC6: 352.45 | DD6: 76.6 | DE6: 248.11 | DF6: 49 | DG6: 204.32 | DH6: 495.44 | DI6: 274.9 | DJ6: 102.53 | DK6: 9.74 | DL6: 70.66 | DM6: 19.8 | DN6: 211.39 | DO6: 39.74 | DP6: 80.09 | DQ6: 261.47 | DR6: 60.97 | DS6: 116.53 | DT6: 139.52 | DU6: 1068.84 | DV6: 27.03 | DW6: 207.15 | DX6: 20.32 | DY6: 270.36 | DZ6: 57.8198 | EA6: 162.22 | EB6: 65.79 | EC6: 30.44 | ED6: 285.5 | EE6: 58.29 | EF6: 31.17 | EG6: 268.13 | EH6: 314.15 | EI6: 247.61 | EJ6: 181.34 | EK6: 386.1 | EL6: 82.07 | EM6: 158.62 | EN6: 209.72 | EO6: 81.54 | EP6: 229.49 | EQ6: 22.04 | ER6: 163.14 | ES6: 58.9 | ET6: 133.54 | EU6: 787.22 | EV6: 349.32 | EW6: 83.53 | EX6: 246.89 | EY6: 434.77 | EZ6: 208.79 | FA6: 211.35 | FB6: 72.48 | FC6: 495.86 | FD6: 82.68 | FE6: 11.96 | FF6: 46.01 | FG6: 31.1386 | FH6: 99.41 | FI6: 462.73 | FJ6: 192.99 | FK6: 39.13 | FL6: 71.29 | FM6: 36.45 | FN6: 236.91 | FO6: 78.33 | FP6: 56.72 | FQ6: 462.21 | FR6: 71.57 | FS6: 118.18 | FT6: 51.19 | FU6: 84.14 | FV6: 102.85 | FW6: 159.38 | FX6: 19.25 | FY6: 641.5 | FZ6: 46.35 | GA6: 32.17 | GB6: 60.8 | GC6: 101.62 | GD6: 110.46 | GE6: 83.61 | GF6: 194.68 | GG6: 115.69 | GH6: 243.59 | GI6: 85.28 | GJ6: 69.5 | GK6: 38.81 | GL6: 73 | GM6: 337.54 | GN6: 336.91 | GO6: 105.43 | GP6: 336.82 | GQ6: 178.45 | GR6: 64.91 | GS6: 83.02 | GT6: 43.95 | GU6: 32.88 | GV6: 58.09 | GW6: 81.56 | GX6: 295.46 | GY6: 115.51 | GZ6: 74.85 | HA6: 57.15 | HB6: 191.66 | HC6: 76 | HD6: 544.93 | HE6: 121.65 | HF6: 114.12 | HG6: 80.04 | HH6: 415.14 | HI6: 231.82 | HJ6: 164.89 | HK6: 524.52 | HL6: 173.97 | HM6: 58.27 | HN6: 234.31 | HO6: 255.28 | HP6: 27.68 | HQ6: 56.39 | HR6: 94.75 | HS6: 419.58 | HT6: 160.81 | HU6: 12.4 | HV6: 112.89 | HW6: 264.21 | HX6: 242.7 | HY6: 296.37 | HZ6: 192.65 | IA6: 37.17 | IB6: 55.59 | IC6: 686.2 | ID6: 273.53 | IE6: 74.52 | IF6: 108.5 | IG6: 927.37 | IH6: 364.1 | II6: 55.46 | IJ6: 60.89 | IK6: 176.99 | IL6: 122.53 | IM6: 141.71 | IN6: 139.9 | IO6: 144.2 | IP6: 401.35 | IQ6: 1964.42 | IR6: 36.47 | IS6: 191.14 | IT6: 66.39 | IU6: 42.42 | IV6: 89.14 | IW6: 57.11 | IX6: 16.43 | IY6: 126.48 | IZ6: 150.75 | JA6: 102.22 | JB6: 228.54 | JC6: 140.25 | JD6: 159.08 | JE6: 154.63 | JF6: 432.36 | JG6: 92.6 | JH6: 17.11 | JI6: 48.97 | JJ6: 46.61 | JK6: 97.73 | JL6: 25.92 | JM6: 48.52 | JN6: 68.68 | JO6: 27.11 | JP6: 112.84 | JQ6: 206.58 | JR6: 219.28 | JS6: 17.12 | JT6: 626.05 | JU6: 127.86 | JV6: 56.38 | JW6: 358.72 | JX6: 266.65 | JY6: 72.74 | JZ6: 44.78 | KA6: 153.95 | KB6: 80.383 | KC6: 191.8 | KD6: 67.52 | KE6: 73.13 | KF6: 174.69 | KG6: 212.37 | KH6: 118.43 | KI6: 126.76 | KJ6: 209.43 | KK6: 590.26 | KL6: 468.85 | KM6: 237.83 | KN6: 180.14 | KO6: 374.2 | KP6: 202.09 | KQ6: 71.97 | KR6: 183.73 | KS6: 8005.95 | KT6: 118.09 | KU6: 179.58 | KV6: 153.96 | KW6: 109.42 | KX6: 102.85 | KY6: 73.66 | KZ6: 302.73 | LA6: 575.22 | LB6: 190.33 | LC6: 92.63 | LD6: 154.03 | LE6: 279.56 | LF6: 29.66 | LG6: 179.19 | LH6: 733.59 | LI6: 222.13 | LJ6: 173.45 | LK6: 243.05 | LL6: 69.93 | LM6: 71.83 | LN6: 115.05 | LO6: 125.19 | LP6: 502 | LQ6: 103.61 | LR6: 357.73 | LS6: 1282.32 | LT6: 127.74 | LU6: 105.5 | LV6: 39.77 | LW6: 211.67 | LX6: 312.2 | LY6: 71.06 | LZ6: 89.24 | MA6: 458.46 | MB6: 140.11 | MC6: 76.02 | MD6: 544.02 | ME6: 183.74 | MF6: 206.96 | MG6: 69.4 | MH6: 580.02 | MI6: 199.71 | MJ6: 82.82 | MK6: 472.1 | ML6: 58.31 | MM6: 4872.42 | MN6: 258.84 | MO6: 93.36 | MP6: 187.91 | MQ6: 35.15 | MR6: 75.19 | MS6: 193.95 | MT6: 128.4 | MU6: 87.5 | MV6: 137 | MW6: 72.54 | MX6: 383.24 | MY6: 229.3 | MZ6: 121.01 | NA6: 78.02 | NB6: 121.86 | NC6: 89.23 | ND6: 326.9 | NE6: 189.66 | NF6: 82.82 | NG6: 68.53 | NH6: 32.2 | NI6: 74.15 | NJ6: 534.93 | NK6: 397 | NL6: 101.54 | NM6: 111.04 | NN6: 129.78 | NO6: 516.4 | NP6: 141.88 | NQ6: 146.57 | NR6: 79.35 | NS6: 57.92 | NT6: 81.17 | NU6: 130.31 | NV6: 205.42 | NW6: 98.54 | NX6: 51.6 | NY6: 23.82 | NZ6: 24.68 | OA6: 182.62 | OB6: 87.01 | OC6: 145.75 | OD6: 195.39 | OE6: 142.34 | OF6: 191.13 | OG6: 312.6 | OH6: 149.34 | OI6: 115.91 | OJ6: 142.33 | OK6: 54.39 | OL6: 121.84 | OM6: 236.17 | ON6: 1246.51 | OO6: 28.83 | OP6: 56.78 | OQ6: 131.7421 | OR6: 87.38 | OS6: 96.04 | OT6: 43.17 | OU6: 272.64 | OV6: 71.34 | OW6: 52.51 | OX6: 191.27 | OY6: 324.79 | OZ6: 48.4053 | PA6: 146.54 | PB6: 143.7 | PC6: 170.99 | PD6: 1049.08 | PE6: 102.57 | PF6: 104.56 | PG6: 32.69 | PH6: 30.67 | PI6: 184.36 | PJ6: 177.83 | PK6: 77.04 | PL6: 118.28 | PM6: 99.47 | PN6: 412.11 | PO6: 9.55 | PP6: 610.72 | PQ6: 215.52 | PR6: 670 | PS6: 97.39 | PT6: 61.42 | PU6: 103.72 | PV6: 88.69 | PW6: 30.42 | PX6: 63.17 | PY6: 86.75 | PZ6: 161.98 | QA6: 517.25 | QB6: 137.15 | QC6: 87.94 | QD6: 394.94 | QE6: 986.1 | QF6: 148.24 | QG6: 92.66 | QH6: 38.92 | QI6: 368.43 | QJ6: 461.96 | QK6: 27.47 | QL6: 38.19 | QM6: 111.39 | QN6: 87.5 | QO6: 215.37 | QP6: 191.98 | QQ6: 77.38 | QR6: 36.34 | QS6: 207.52 | QT6: 254.69 | QU6: 165.02 | QV6: 951.04 | QW6: 180.87 | QX6: 298.99 | QY6: 49.15 | QZ6: 68.96 | RA6: 32.61 | RB6: 420.01 | RC6: 68.45 | RD6: 91.79 | RE6: 130.8 | RF6: 102.92 | RG6: 173.72 | RH6: 102 | RI6: 91.88 | RJ6: 243.84 | RK6: 329.2 | RL6: 31.12 | RM6: 16.96 | RN6: 39.23 | RO6: 60.91 | RP6: 31.86 | RQ6: 10.06 | RR6: 510.3 | RS6: 51.93 | RT6: 43.44 | RU6: 23.68 | RV6: 68.23 | RW6: 172.83 | RX6: 92.26 | RY6: 86.26 | RZ6: 207.4365 | SA6: 40.81 | SB6: 412.69 | SC6: 366.48 | SD6: 21.1 | SE6: 260.01
B7: 45671 | C7: 75.31 | D7: 300.36 | E7: 38.28 | F7: 1328.31 | G7: 224.7 | H7: 167.02 | I7: 371.57 | J7: 247.47 | K7: 156.9 | L7: 62.04 | M7: 175.55 | N7: 108.12 | O7: 358.42 | P7: 148.83 | Q7: 109.72 | R7: 117.27 | S7: 176.86 | T7: 32.67 | U7: 392.78 | V7: 589.86 | W7: 217.75 | X7: 144.75 | Y7: 388.74 | Z7: 281.58 | AA7: 99.65 | AB7: 137.21 | AC7: 122.52 | AD7: 45.78 | AE7: 26.41 | AF7: 159.74 | AG7: 21.8 | AH7: 236.93 | AI7: 119.47 | AJ7: 214.65 | AK7: 90.79 | AL7: 59.33 | AM7: 19.2 | AN7: 50.94 | AO7: 415.67 | AP7: 69.38 | AQ7: 285.03 | AR7: 29.12 | AS7: 73.5 | AT7: 72.59 | AU7: 51.36 | AV7: 305.79 | AW7: 55.42 | AX7: 22.54 | AY7: 113.02 | AZ7: 103.65 | BA7: 307.96 | BB7: 229.73 | BC7: 45.66 | BD7: 627.71 | BE7: 51.19 | BF7: 492.91 | BG7: 291.69 | BH7: 273.49 | BI7: 3227.8 | BJ7: 189.31 | BK7: 585.8 | BL7: 54.38 | BM7: 579.8 | BN7: 70.5 | BO7: 75.94 | BP7: 30.62 | BQ7: 235.8 | BR7: 450.03 | BS7: 82.8 | BT7: 95.65 | BU7: 55.74 | BV7: 34.44 | BW7: 28.86 | BX7: 244.97 | BY7: 24.51 | BZ7: 154.25 | CA7: 41.19 | CB7: 159.03 | CC7: 203.26 | CD7: 65.56 | CE7: 87.67 | CF7: 226.8 | CG7: 26.05 | CH7: 89.37 | CI7: 47.43 | CJ7: 197.48 | CK7: 364.25 | CL7: 237.62 | CM7: 136.47 | CN7: 192.6 | CO7: 432.31 | CP7: 53.69 | CQ7: 116.76 | CR7: 188.8 | CS7: 57.79 | CT7: 123.52 | CU7: 106.85 | CV7: 70.66 | CW7: 340.14 | CX7: 233.9 | CY7: 120.73 | CZ7: 109.06 | DA7: 119.79 | DB7: 135.77 | DC7: 362.65 | DD7: 77.56 | DE7: 252.34 | DF7: 50.69 | DG7: 197.96 | DH7: 499.8 | DI7: 277.62 | DJ7: 103.63 | DK7: 9.78 | DL7: 67.98 | DM7: 19.41 | DN7: 212.27 | DO7: 39.5 | DP7: 79.17 | DQ7: 265.12 | DR7: 58.78 | DS7: 117.02 | DT7: 140.72 | DU7: 1087.88 | DV7: 28.2 | DW7: 214.89 | DX7: 20.14 | DY7: 267.04 | DZ7: 58.2718 | EA7: 155.31 | EB7: 66.06 | EC7: 30.01 | ED7: 289.11 | EE7: 57.1 | EF7: 31.86 | EG7: 282.63 | EH7: 313.24 | EI7: 252.97 | EJ7: 186.56 | EK7: 382.71 | EL7: 83.67 | EM7: 160.5 | EN7: 210.63 | EO7: 81.43 | EP7: 227.12 | EQ7: 22.01 | ER7: 156.31 | ES7: 59.92 | ET7: 135.18 | EU7: 744.91 | EV7: 346.29 | EW7: 83.43 | EX7: 251.19 | EY7: 428.21 | EZ7: 214.54 | FA7: 213.37 | FB7: 75.86 | FC7: 484.47 | FD7: 85.25 | FE7: 11.72 | FF7: 51.57 | FG7: 31.4858 | FH7: 97.36 | FI7: 460.84 | FJ7: 193.37 | FK7: 40.16 | FL7: 71.17 | FM7: 36.73 | FN7: 239.24 | FO7: 78.84 | FP7: 55.98 | FQ7: 475.5 | FR7: 71.19 | FS7: 121.75 | FT7: 52.08 | FU7: 84.76 | FV7: 106.04 | FW7: 156.72 | FX7: 16.22 | FY7: 647.01 | FZ7: 46.85 | GA7: 31.98 | GB7: 61.47 | GC7: 104.88 | GD7: 112.5 | GE7: 83.24 | GF7: 195.71 | GG7: 116.53 | GH7: 239.76 | GI7: 85.06 | GJ7: 58.43 | GK7: 39.87 | GL7: 72.34 | GM7: 341.64 | GN7: 328.96 | GO7: 101.91 | GP7: 340.31 | GQ7: 179.15 | GR7: 64.84 | GS7: 82.05 | GT7: 43.91 | GU7: 33.13 | GV7: 58.59 | GW7: 82.36 | GX7: 289.98 | GY7: 114.91 | GZ7: 73.94 | HA7: 60.89 | HB7: 193.5 | HC7: 78.04 | HD7: 556.99 | HE7: 119.24 | HF7: 114.03 | HG7: 80.21 | HH7: 404.06 | HI7: 229.38 | HJ7: 164.26 | HK7: 543.74 | HL7: 169.32 | HM7: 58.1 | HN7: 234.5 | HO7: 260.07 | HP7: 28.96 | HQ7: 58.06 | HR7: 94.58 | HS7: 412.71 | HT7: 170.51 | HU7: 11.85 | HV7: 111.24 | HW7: 267.1 | HX7: 233.28 | HY7: 286.87 | HZ7: 192.28 | IA7: 36.38 | IB7: 54.19 | IC7: 701.26 | ID7: 276.43 | IE7: 71.89 | IF7: 110.2 | IG7: 917.23 | IH7: 362.8 | II7: 55.46 | IJ7: 59.82 | IK7: 173.65 | IL7: 124.03 | IM7: 139.49 | IN7: 143.16 | IO7: 141.75 | IP7: 399.78 | IQ7: 1949.53 | IR7: 36.87 | IS7: 195.02 | IT7: 64.08 | IU7: 42.89 | IV7: 91 | IW7: 56.62 | IX7: 16.59 | IY7: 126.87 | IZ7: 143.06 | JA7: 101.63 | JB7: 232.65 | JC7: 141.71 | JD7: 159.53 | JE7: 149.12 | JF7: 418.63 | JG7: 93.07 | JH7: 17.48 | JI7: 48.82 | JJ7: 46.54 | JK7: 95.44 | JL7: 26 | JM7: 49.06 | JN7: 71.25 | JO7: 27.14 | JP7: 112.11 | JQ7: 207.17 | JR7: 182.2 | JS7: 16.58 | JT7: 623.8 | JU7: 124.62 | JV7: 56.88 | JW7: 348.04 | JX7: 265.51 | JY7: 70.2 | JZ7: 45.7 | KA7: 155.97 | KB7: 80.289 | KC7: 186.81 | KD7: 69.92 | KE7: 71.93 | KF7: 173.57 | KG7: 218.21 | KH7: 117.61 | KI7: 125.84 | KJ7: 207.57 | KK7: 593.73 | KL7: 484.46 | KM7: 240.05 | KN7: 184.72 | KO7: 404.93 | KP7: 207.41 | KQ7: 70.17 | KR7: 182.04 | KS7: 8143.64 | KT7: 116.69 | KU7: 183.62 | KV7: 162 | KW7: 109.39 | KX7: 104.04 | KY7: 73.87 | KZ7: 294.19 | LA7: 570.27 | LB7: 184.16 | LC7: 91.57 | LD7: 152.98 | LE7: 276.98 | LF7: 28.71 | LG7: 178.8 | LH7: 690.87 | LI7: 217.76 | LJ7: 172.37 | LK7: 237.53 | LL7: 70.29 | LM7: 70.27 | LN7: 119.19 | LO7: 134.06 | LP7: 490.36 | LQ7: 102.84 | LR7: 348.99 | LS7: 1300.73 | LT7: 124.71 | LU7: 108.12 | LV7: 39.17 | LW7: 209 | LX7: 319.89 | LY7: 71.27 | LZ7: 89.4 | MA7: 454.17 | MB7: 131.76 | MC7: 77.17 | MD7: 538.88 | ME7: 180.03 | MF7: 207 | MG7: 64.41 | MH7: 571.53 | MI7: 195.02 | MJ7: 78.11 | MK7: 462.58 | ML7: 55.18 | MM7: 4778.81 | MN7: 258.11 | MO7: 90.58 | MP7: 178.08 | MQ7: 37.18 | MR7: 74.73 | MS7: 189.66 | MT7: 129.75 | MU7: 82.84 | MV7: 143.43 | MW7: 71.56 | MX7: 393.16 | MY7: 231.73 | MZ7: 119.43 | NA7: 76.25 | NB7: 118.47 | NC7: 89.4 | ND7: 323.54 | NE7: 197.43 | NF7: 83.83 | NG7: 67.66 | NH7: 32.14 | NI7: 71.04 | NJ7: 526.67 | NK7: 394.4 | NL7: 104.71 | NM7: 112.52 | NN7: 124.91 | NO7: 509.02 | NP7: 139.16 | NQ7: 145.25 | NR7: 78.35 | NS7: 56.44 | NT7: 81.8 | NU7: 131.28 | NV7: 204.74 | NW7: 99.79 | NX7: 50.1 | NY7: 24 | NZ7: 27.14 | OA7: 183.19 | OB7: 94.99 | OC7: 152.76 | OD7: 191.05 | OE7: 143.11 | OF7: 185.35 | OG7: 309.09 | OH7: 151.37 | OI7: 115.42 | OJ7: 149.42 | OK7: 53.18 | OL7: 116.09 | OM7: 228.83 | ON7: 1271.36 | OO7: 28.97 | OP7: 56.22 | OQ7: 133.7712 | OR7: 92.63 | OS7: 92.49 | OT7: 34.46 | OU7: 284.46 | OV7: 69.61 | OW7: 53.15 | OX7: 198.1 | OY7: 339.68 | OZ7: 47.4078 | PA7: 144.95 | PB7: 142.9 | PC7: 177.68 | PD7: 1031.29 | PE7: 105.28 | PF7: 103.97 | PG7: 33.1 | PH7: 30.93 | PI7: 185.5 | PJ7: 181.62 | PK7: 75.06 | PL7: 125.58 | PM7: 100.28 | PN7: 411.66 | PO7: 9.52 | PP7: 594.25 | PQ7: 214.18 | PR7: 729.86 | PS7: 97.81 | PT7: 66.29 | PU7: 107.67 | PV7: 91.23 | PW7: 30.41 | PX7: 63.4 | PY7: 82.42 | PZ7: 159.33 | QA7: 517.68 | QB7: 134.18 | QC7: 87.18 | QD7: 396.36 | QE7: 963.17 | QF7: 143.65 | QG7: 91.99 | QH7: 40.08 | QI7: 358.34 | QJ7: 465.93 | QK7: 27.55 | QL7: 37.92 | QM7: 108.1 | QN7: 86.67 | QO7: 210.46 | QP7: 201.38 | QQ7: 81.61 | QR7: 37.29 | QS7: 206.14 | QT7: 246.03 | QU7: 164.41 | QV7: 898.09 | QW7: 173.89 | QX7: 294.03 | QY7: 45 | QZ7: 70.19 | RA7: 30.53 | RB7: 427.29 | RC7: 68.4 | RD7: 91.78 | RE7: 127.6 | RF7: 104.12 | RG7: 169.33 | RH7: 102.37 | RI7: 89.11 | RJ7: 288.87 | RK7: 321.09 | RL7: 31.14 | RM7: 17.28 | RN7: 38.81 | RO7: 61.21 | RP7: 31.69 | RQ7: 9.73 | RR7: 510.69 | RS7: 52.93 | RT7: 45.07 | RU7: 24.85 | RV7: 65.91 | RW7: 170.58 | RX7: 94.5 | RY7: 84.13 | RZ7: 205.8631 | SA7: 41.76 | SB7: 416.08 | SC7: 382.26 | SD7: 21.03 | SE7: 255.37
